Workbook
Name akontinent: [1]Svyhledat!$B$17
Name anika: [1]Svyhledat!$C$17
Name b: [1]Sifrovani!#REF!
Name be: '[2]kvadraticka rovnice'!$E$4
Name ce: [1]Sifrovani!#REF!
Name cecko: '[2]kvadraticka rovnice'!$E$5
Name Cena: #REF!
Name Cena_DM: #REF!
Name Cena_Kč: #REF!
Name ceník_výrobků: #REF!
Name Clo: #REF!
Name Doprava: #REF!
Name DPH_1: #REF!
Name DPH_2: #REF!
Name DPH_Doprava: #REF!
Name DPH_Zboží: #REF!
Name Instalace: #REF!
Name kontinenty: [1]Svyhledat!$A$21:$A$25
Name kontynentiky: [1]Svyhledat!$B$2:$B$15
Name Kurz: #REF!
Name Legenda: [3]Knihy!$A$9,[3]Knihy!$A$3:$A$9,[3]Knihy!$B$3:$G$3
Name morseovka: morseovka!$A$1:$B$27
Name mzdy_legenda: '[3]Mzdy '!$A$3:$A$10,'[3]Mzdy '!$B$3:$I$3
Name mzdy_vzorce: '[3]Mzdy '!$F$4:$J$10,'[3]Mzdy '!$B$10:$C$10,'[3]Mzdy '!$D$10,'[3]Mzdy '!$E$10,'[3]Mzdy '!$E$4:$E$9
Name niky: [1]Svyhledat!$B$20:$D$20
Name Nový_textový_dokument: Burzovní_graf!$A$1:$I$22
Name Příplatek: [3]Mzdy2!#REF!
Name Sazba_cla: #REF!
Name Titul_a_součty: [3]Trafika!$A$3:$J$3,[3]Trafika!$A$23:$J$23
Name Vstup: [1]Sifrovani!$C$4
Name Vypočtené_clo: #REF!
Name Výpočty: [3]Knihy!$G$4:$G$9,[3]Knihy!$B$9:$F$9
Name x: #REF!

Sheet Prodej
C2: prodeje (v tis. €)
B3: období firma | C3: I-06 | D3: IV-06 | E3: VII-06 | F3: X-06 | G3: I-07 | H3: IV-07 | I3: VII-07 | J3: X-07 | K3: I-08 | L3: IV-08 | M3: průměr za sledované období | N3: celkem
B4: Firma A | C4: 192687.5 | D4: 698825.91 | E4: -2797.97 | F4: 698825.91 | G4: 8429490.9 | H4: 1068032.1 | I4: 10479365 | J4: 10537697 | K4: 10680532 | L4: 8399825.3 | M4: =AVERAGE(C4:L4) -> 5118248.5 | N4: =SUM(C4:L4) -> 51182485
B5: Firma B | C5: 58332.12 | D5: 1071124.2 | E5: 84581.58 | F5: 1068032.1 | G5: 9132699.8 | H5: 1848095.9 | I5: 916436.84 | J5: 927666 | K5: 1848095.9 | L5: 721645.31 | M5: =AVERAGE(C5:L5) -> 1767671 | N5: =SUM(C5:L5) -> 17676710
B6: Firma C | C6: 11229.16 | D6: 1149270 | E6: 732874.47 | F6: 1848095.9 | G6: 1894968.7 | H6: 2860445 | I6: 1476320.8 | J6: 1506320.5 | K6: 2860445 | L6: 1143323.6 | M6: =AVERAGE(C6:L6) -> 1548329.3 | N6: =SUM(C6:L6) -> 15483293
B7: Firma D | C7: 29999.75 | D7: 1789320.8 | E7: 1173323.4 | F7: 2860445 | G7: 2029281.3 | H7: 1182040.8 | I7: 1119020 | J7: 1151790.8 | K7: 1182040.8 | L7: 853186.88 | M7: =AVERAGE(C7:L7) -> 1337045 | N7: =SUM(C7:L7) -> 13370450
B8: Firma E | C8: 32770.81 | D8: 32770.81 | E8: 885957.69 | F8: 1182040.8 | G8: 856162.33 | H8: 1795388.4 | I8: -4900.73 | J8: 1166.84 | K8: 1795388.4 | L8: -3092.13 | M8: =AVERAGE(C8:L8) -> 657365.32 | N8: =SUM(C8:L8) -> 6573653.2
B9: Firma F | C9: 6067.57 | D9: 6067.57 | E9: 2975.45 | F9: 1795388.4 | G9: 741571.61 | H9: 45837.84 | I9: 942972.68 | J9: 988810.51 | K9: 45837.84 | L9: 698825.91 | M9: =AVERAGE(C9:L9) -> 527435.54 | N9: =SUM(C9:L9) -> 5274355.4
B10: Firma G | C10: 45837.84 | D10: 45837.84 | E10: 744663.74 | F10: 4583557.8 | G10: 1855658.4 | H10: 85708.28 | I10: 1464144.8 | J10: 1549853 | K10: 85708.28 | L10: 1071124.2 | M10: =AVERAGE(C10:L10) -> 1153209.4 | N10: =SUM(C10:L10) -> 11532094
B11: Firma H | C11: 85708.28 | D11: 85708.28 | E11: 1901496.2 | F11: 131546.11 | G11: 2929758.1 | H11: 1881096.6 | I11: 440916.35 | J11: 9173738.8 | K11: 2725481.7 | L11: 5720890.1 | M11: =AVERAGE(C11:L11) -> 2507634.1 | N11: =SUM(C11:L11) -> 25076341
B12: Firma I | C12: 108854.09 | D12: 108854.09 | E12: 1156832.5 | F12: 85708.28 | G12: 1074099.7 | H12: 1795388.4 | I12: 657662.07 | J12: 1702473.4 | K12: 2037748.5 | L12: 2364081.6 | M12: =AVERAGE(C12:L12) -> 1109170.3 | N12: =SUM(C12:L12) -> 11091703
B13: Firma J | C13: 195998.63 | D13: 195540.3 | E13: 1786228.7 | F13: 2624498 | G13: 1899585.5 | H13: 2136064.2 | I13: 16799651 | J13: 1141515 | K13: 4142.29 | L13: 3590776.8 | M13: =AVERAGE(C13:L13) -> 3037400 | N13: =SUM(C13:L13) -> 30374000
B14: Firma K | C14: 207954.01 | D14: 2080227.6 | E14: 698825.91 | F14: 166125.06 | G14: 1660540.5 | H14: 3696191.8 | I14: 1443290.6 | J14: 1097333.7 | K14: 3813014.3 | L14: 2171215.8 | M14: =AVERAGE(C14:L14) -> 1703471.9 | N14: =SUM(C14:L14) -> 17034719
B15: Firma L | C15: 194791.53 | D15: 253123.65 | E15: 1071124.2 | F15: 8732822.4 | G15: 2679643.9 | H15: 5720890.1 | I15: 2286647.2 | J15: 389928.43 | K15: 2901477.1 | L15: 366208.07 | M15: =AVERAGE(C15:L15) -> 2459665.7 | N15: =SUM(C15:L15) -> 24596657
... B29: Firma Z | C29: 45837.84 | D29: 1795388.4 | E29: 732874.47 | F29: 865290.94 | G29: 1899585.5 | H29: 698825.91 | I29: 1182040.8 | J29: 742855.14 | K29: 440916.35 | L29: 85708.28 | M29: =AVERAGE(C29:L29) -> 848932.36 | N29: =SUM(C29:L29) -> 8489323.6
B30: průměr za čtvrtletí | C30: =AVERAGE(C4:C29) -> 227747.07 | D30: =AVERAGE(D4:D29) -> 918605.63 | E30: =AVERAGE(E4:E29) -> 906792.37 | F30: =AVERAGE(F4:F29) -> 2351025.4 | G30: =AVERAGE(G4:G29) -> 2087690.2 | H30: =AVERAGE(H4:H29) -> 2197254.7 | I30: =AVERAGE(I4:I29) -> 2648547.2 | J30: =AVERAGE(J4:J29) -> 2390798.9 | ... L30: =AVERAGE(L4:L29) -> 1591467.9
B31: "horních 10%"

Sheet Top5
C2: prodeje (v tis. €)
B3: období firma | C3: I-06 | D3: IV-06 | E3: VII-06 | F3: X-06 | G3: I-07 | H3: IV-07 | I3: VII-07 | J3: X-07 | K3: I-08 | L3: IV-08 | M3: celkem
B4: Firma A | C4: 192687.5 | D4: 698825.91 | E4: -2797.97 | F4: 698825.91 | G4: 8429490.9 | H4: 1068032.1 | I4: 10479365 | J4: 10537697 | K4: 10680532 | L4: 8399825.3 | M4: 51182485
B5: Firma H | C5: 85708.28 | D5: 85708.28 | E5: 1901496.2 | F5: 131546.11 | G5: 2929758.1 | H5: 1881096.6 | I5: 440916.35 | J5: 9173738.8 | K5: 2725481.7 | L5: 5720890.1 | M5: 25076341
B6: Firma J | C6: 195998.63 | D6: 195540.3 | E6: 1786228.7 | F6: 2624498 | G6: 1899585.5 | H6: 2136064.2 | I6: 16799651 | J6: 1141515 | K6: 4142.29 | L6: 3590776.8 | M6: 30374000
B7: Firma U | C7: -2866.47 | D7: 732874.47 | E7: 1848095.9 | F7: 1866989.7 | G7: 698825.91 | H7: 8429490.9 | I7: 294725.45 | J7: 3590776.8 | K7: 8729730.3 | L7: 85708.28 | M7: 26274351
B8: Firma V | C8: 83998.26 | D8: 1173323.4 | E8: 2860445 | F8: 10487439 | G8: 1068032.1 | H8: 9132699.8 | I8: 1139742.2 | J8: 440916.35 | K8: 1686304.4 | L8: 2037748.5 | M8: 30110649
B9: celkem za čtvrtletí | C9: 5921423.8 | D9: 23883746 | E9: 23576602 | F9: 61126661 | G9: 54279944 | H9: 57128621 | I9: 68862228 | J9: 62160771 | K9: 61073587 | L9: 41378166 | M9: =SUM(C9:L9) -> 4.5939175e+08
B11: kurz ČNB | C11: 39712 | D11: 24.25
C13: prodeje (v tis. Kč)
B14: období firma | C14: I-06 | D14: IV-06 | E14: VII-06 | F14: X-06 | G14: I-07 | H14: IV-07 | I14: VII-07 | J14: X-07 | K14: I-08 | L14: IV-08 | M14: celkem
B15: Firma A | C15: =C4*$D$11 -> 4672671.9 | D15: =D4*$D$11 -> 16946528 | E15: =E4*$D$11 -> -67850.772 | F15: =F4*$D$11 -> 16946528 | G15: =G4*$D$11 -> 2.0441516e+08 | H15: =H4*$D$11 -> 25899778 | I15: =I4*$D$11 -> 2.5412461e+08 | J15: =J4*$D$11 -> 2.5553916e+08 | ... M15: =M4*$D$11 -> 1.2411753e+09
B16: Firma H | C16: =C5*$D$11 -> 2078425.8 | D16: =D5*$D$11 -> 2078425.8 | E16: =E5*$D$11 -> 46111284 | F16: =F5*$D$11 -> 3189993.2 | G16: =G5*$D$11 -> 71046633 | H16: =H5*$D$11 -> 45616594 | I16: =I5*$D$11 -> 10692221 | J16: =J5*$D$11 -> 2.2246317e+08 | ... M16: =M5*$D$11 -> 6.0810126e+08
B17: Firma J | C17: =C6*$D$11 -> 4752966.8 | D17: =D6*$D$11 -> 4741852.3 | E17: =E6*$D$11 -> 43316046 | F17: =F6*$D$11 -> 63644077 | G17: =G6*$D$11 -> 46064948 | H17: =H6*$D$11 -> 51799557 | I17: =I6*$D$11 -> 4.0739153e+08 | J17: =J6*$D$11 -> 27681739 | ... M17: =M6*$D$11 -> 7.365695e+08
B18: Firma U | C18: =C7*$D$11 -> -69511.897 | D18: =D7*$D$11 -> 17772206 | E18: =E7*$D$11 -> 44816326 | F18: =F7*$D$11 -> 45274500 | G18: =G7*$D$11 -> 16946528 | H18: =H7*$D$11 -> 2.0441516e+08 | I18: =I7*$D$11 -> 7147092.2 | J18: =J7*$D$11 -> 87076336 | ... M18: =M7*$D$11 -> 6.3715302e+08
B19: Firma V | C19: =C8*$D$11 -> 2036957.8 | D19: =D8*$D$11 -> 28453091 | E19: =E8*$D$11 -> 69365792 | F19: =F8*$D$11 -> 2.5432039e+08 | G19: =G8*$D$11 -> 25899778 | H19: =H8*$D$11 -> 2.2146797e+08 | I19: =I8*$D$11 -> 27638750 | J19: =J8*$D$11 -> 10692221 | ... M19: =M8*$D$11 -> 7.3018323e+08
B20: celkem za čtvrtletí | C20: =C9*$D$11 -> 1.4359453e+08 | D20: =D9*$D$11 -> 5.7918085e+08 | E20: =E9*$D$11 -> 5.7173259e+08 | F20: =F9*$D$11 -> 1.4823215e+09 | G20: =G9*$D$11 -> 1.3162886e+09 | H20: =H9*$D$11 -> 1.3853691e+09 | I20: =I9*$D$11 -> 1.669909e+09 | J20: =J9*$D$11 -> 1.5073987e+09 | ... L20: =L9*$D$11 -> 1.0034205e+09 | M20: =SUM(C20:L20) -> 1.114025e+10
C25: podíly na prodeji (v %)
B26: období firma | C26: I-06 | D26: IV-06 | E26: VII-06 | F26: X-06 | G26: I-07 | H26: IV-07 | I26: VII-07 | J26: X-07 | K26: I-08 | L26: IV-08 | M26: celkem
B27: Firma A | C27: =C15 / C$20 -> 0.032540738 | D27: =D15 / D$20 -> 0.029259476 | E27: =E15 / E$20 -> -0.00011867571 | F27: =F15 / F$20 -> 0.011432424 | G27: =G15 / G$20 -> 0.1552966 | H27: =H15 / H$20 -> 0.018695219 | I27: =I15 / I$20 -> 0.15217872 | J27: =J15 / J$20 -> 0.16952328 | ... L27: =L15 / L$20 -> 0.20300139 | M27: =SUM(C27:L27) -> 0.94668889
B28: Firma H | C28: =C16 / C$20 -> 0.014474269 | D28: =D16 / D$20 -> 0.003588561 | E28: =E16 / E$20 -> 0.080651837 | F28: =F16 / F$20 -> 0.0021520251 | G28: =G16 / G$20 -> 0.053974965 | H28: =H16 / H$20 -> 0.032927394 | I28: =I16 / I$20 -> 0.0064028767 | J28: =J16 / J$20 -> 0.14758084 | ... L28: =L16 / L$20 -> 0.13825867 | M28: =SUM(C28:L28) -> 0.52463763
B29: Firma J | C29: =C17 / C$20 -> 0.033099916 | D29: =D17 / D$20 -> 0.0081871703 | E29: =E17 / E$20 -> 0.075762772 | F29: =F17 / F$20 -> 0.042935406 | G29: =G17 / G$20 -> 0.034996084 | H29: =H17 / H$20 -> 0.037390438 | I29: =I17 / I$20 -> 0.24396031 | J29: =J17 / J$20 -> 0.018363914 | ... L29: =L17 / L$20 -> 0.086779506 | M29: =SUM(C29:L29) -> 0.58154334
B30: Firma U | C30: =C18 / C$20 -> -0.00048408459 | D30: =D18 / D$20 -> 0.030685072 | E30: =E18 / E$20 -> 0.078386866 | F30: =F18 / F$20 -> 0.030542969 | G30: =G18 / G$20 -> 0.012874477 | H30: =H18 / H$20 -> 0.14755285 | I30: =I18 / I$20 -> 0.0042799291 | J30: =J18 / J$20 -> 0.057765963 | ... L30: =L18 / L$20 -> 0.0020713407 | M30: =SUM(C30:L30) -> 0.50661328
B31: Firma V | C31: =C19 / C$20 -> 0.014185484 | D31: =D19 / D$20 -> 0.049126437 | E31: =E19 / E$20 -> 0.12132559 | F31: =F19 / F$20 -> 0.17156898 | G31: =G19 / G$20 -> 0.019676367 | H31: =H19 / H$20 -> 0.15986207 | I31: =I19 / I$20 -> 0.016551051 | J31: =J19 / J$20 -> 0.0070931609 | ... L31: =L19 / L$20 -> 0.049246952 | M31: =SUM(C31:L31) -> 0.63624711
B32: celkem za čtvrtletí | C32: =SUM(C27:C31) -> 0.093816322 | D32: =SUM(D27:D31) -> 0.12084672 | E32: =SUM(E27:E31) -> 0.35600839 | F32: =SUM(F27:F31) -> 0.2586318 | G32: =SUM(G27:G31) -> 0.2768185 | H32: =SUM(H27:H31) -> 0.39642797 | I32: =SUM(I27:I31) -> 0.42337288 | J32: =SUM(J27:J31) -> 0.40032715 | ... L32: =SUM(L27:L31) -> 0.47935786 | M32: =SUM(C32:L32) -> 3.1957303

Sheet Banky
D1: CZ65 0300 0000 0002 1962 3990
A2: IBAN | B2: Pohyb na účtu
A3: CZ65 0300 0000 0002 1962 3990 | B3: 354912 | C3: =MID(A3,6,4) -> 0300 | E3: {=_xlfn.UNIQUE(C3:C56)} -> 0300 | F3: =SUMIF($C$3:$C$56,E3,$B$3:$B$56) -> 6815275
A4: CZ65 0300 0080 1018 0308 5233 | B4: 194727 | C4: =MID(A4,6,4) -> 0300 | E4: 0710 | F4: =SUMIF($C$3:$C$56,E4,$B$3:$B$56) -> 10512585
A5: CZ65 0710 0077 0400 0762 1491 | B5: 233667 | C5: =MID(A5,6,4) -> 0710 | E5: 0100 | F5: =SUMIF($C$3:$C$56,E5,$B$3:$B$56) -> 3034855
A6: CZ65 0100 0000 0000 1810 8511 | B6: 923567 | C6: =MID(A6,6,4) -> 0100 | E6: 2400 | F6: =SUMIF($C$3:$C$56,E6,$B$3:$B$56) -> 7124524
A7: CZ65 0710 0000 0000 0093 1761 | B7: 508935 | C7: =MID(A7,6,4) -> 0710
A8: CZ65 2400 0000 0019 2120 0001 | B8: 653806 | C8: =MID(A8,6,4) -> 2400
A9: CZ65 0710 0200 0100 0603 6231 | B9: 604148 | C9: =MID(A9,6,4) -> 0710
A10: CZ21 2400 0000 0053 1410 1034 | B10: 121057 | C10: =MID(A10,6,4) -> 2400
A11: CZ65 0300 0000 0001 6262 6014 | B11: 479159 | C11: =MID(A11,6,4) -> 0300
A12: CZ65 0300 0000 0002 1962 3990 | B12: 194705 | C12: =MID(A12,6,4) -> 0300
A13: CZ65 0300 0080 1018 0308 5233 | B13: 88129 | C13: =MID(A13,6,4) -> 0300
A14: CZ65 0710 0077 0400 0762 1491 | B14: 931019 | C14: =MID(A14,6,4) -> 0710
A15: CZ65 0100 0000 0000 1810 8511 | B15: 476360 | C15: =MID(A15,6,4) -> 0100
A16: CZ65 0710 0000 0000 0093 1761 | B16: 737868 | C16: =MID(A16,6,4) -> 0710
A17: CZ65 2400 0000 0019 2120 0001 | B17: 347660 | C17: =MID(A17,6,4) -> 2400
A18: CZ65 0710 0200 0100 0603 6231 | B18: 922892 | C18: =MID(A18,6,4) -> 0710
... A56: CZ65 0300 0000 0001 6262 6014 | B56: 254874 | C56: =MID(A56,6,4) -> 0300

Sheet Grafy funkcí řešení
A2: x | B2: y | D2: a | E2: b | F2: c
A3: -10 | B3: =$D$3*A3^2+$E$3*A3+$F$3 -> 100 | D3: 1 | E3: 0 | F3: 0
A4: -9.5 | B4: =$D$3*A4^2+$E$3*A4+$F$3 -> 90.25
A5: -9 | B5: =$D$3*A5^2+$E$3*A5+$F$3 -> 81
A6: -8.5 | B6: =$D$3*A6^2+$E$3*A6+$F$3 -> 72.25
A7: -8 | B7: =$D$3*A7^2+$E$3*A7+$F$3 -> 64
A8: -7.5 | B8: =$D$3*A8^2+$E$3*A8+$F$3 -> 56.25
A9: -7 | B9: =$D$3*A9^2+$E$3*A9+$F$3 -> 49
A10: -6.5 | B10: =$D$3*A10^2+$E$3*A10+$F$3 -> 42.25
A11: -6 | B11: =$D$3*A11^2+$E$3*A11+$F$3 -> 36
A12: -5.5 | B12: =$D$3*A12^2+$E$3*A12+$F$3 -> 30.25
A13: -5 | B13: =$D$3*A13^2+$E$3*A13+$F$3 -> 25
A14: -4.5 | B14: =$D$3*A14^2+$E$3*A14+$F$3 -> 20.25
A15: -4 | B15: =$D$3*A15^2+$E$3*A15+$F$3 -> 16
... A43: 10 | B43: =$D$3*A43^2+$E$3*A43+$F$3 -> 100

Sheet prodeje_firem_zdroj
A1: firma | B1: datum vystavení faktury | C1: datum splatnosti faktury | D1: datum uhrazení faktury | E1: uhrazeno x dnů před dnem splatnosti | F1: částka na faktuře | G1: skutečně uhrazeno | H1: rozdíl fakturované a zaplacené čásky | I1: přepočet faktur na Kč | J1: den v týdnu kdy byla faktura uhrazena
A2: Firma A | B2: 38716 | C2: =EDATE(Tabulka1[[#This Row],[datum vystavení faktury]],1) -> 38747 | D2: 38796 | E2: =_xlfn.DAYS(Tabulka1[[#This Row],[datum uhrazení faktury]],Tabulka1[[#This Row],[datum splatnosti faktury]]) -> 49 | F2: 65036.79 | G2: 65036.79 | H2: =Tabulka1[[#This Row],[částka na faktuře]] - Tabulka1[[#This Row],[skutečně uhrazeno]] -> 0 | I2: {=_xlfn.SWITCH(Tabulka1[[#This Row],[firma]],firmy_MK!A1,Tabulka1[[#This Row],[částka na faktuře]]*firmy_MK!C1)} -> 1635675.3 | J2: =WEEKDAY(Tabulka1[[#This Row],[datum uhrazení faktury]],2) -> 1
A3: Firma A | B3: 38716 | C3: =EDATE(Tabulka1[[#This Row],[datum vystavení faktury]],1) -> 38747 | D3: 38772 | E3: =_xlfn.DAYS(Tabulka1[[#This Row],[datum uhrazení faktury]],Tabulka1[[#This Row],[datum splatnosti faktury]]) -> 25 | F3: 108011.76 | G3: 108011.76 | H3: =Tabulka1[[#This Row],[částka na faktuře]] - Tabulka1[[#This Row],[skutečně uhrazeno]] -> 0 | I3: {=_xlfn.SWITCH(Tabulka1[[#This Row],[firma]],firmy_MK!A2,Tabulka1[[#This Row],[částka na faktuře]]*firmy_MK!C2)} -> #N/A | J3: =WEEKDAY(Tabulka1[[#This Row],[datum uhrazení faktury]],2) -> 5
A4: Firma A | B4: 38716 | C4: =EDATE(Tabulka1[[#This Row],[datum vystavení faktury]],1) -> 38747 | D4: 38744 | E4: =_xlfn.DAYS(Tabulka1[[#This Row],[datum uhrazení faktury]],Tabulka1[[#This Row],[datum splatnosti faktury]]) -> -3 | F4: 137151.36 | G4: 137151.36 | H4: =Tabulka1[[#This Row],[částka na faktuře]] - Tabulka1[[#This Row],[skutečně uhrazeno]] -> 0 | I4: {=_xlfn.SWITCH(Tabulka1[[#This Row],[firma]],firmy_MK!A3,Tabulka1[[#This Row],[částka na faktuře]]*firmy_MK!C3)} -> #N/A | J4: =WEEKDAY(Tabulka1[[#This Row],[datum uhrazení faktury]],2) -> 5
A5: Firma A | B5: 38719 | C5: =EDATE(Tabulka1[[#This Row],[datum vystavení faktury]],1) -> 38750 | D5: 38768 | E5: =_xlfn.DAYS(Tabulka1[[#This Row],[datum uhrazení faktury]],Tabulka1[[#This Row],[datum splatnosti faktury]]) -> 18 | F5: 26302.85 | G5: 26302.85 | H5: =Tabulka1[[#This Row],[částka na faktuře]] - Tabulka1[[#This Row],[skutečně uhrazeno]] -> 0 | I5: {=_xlfn.SWITCH(Tabulka1[[#This Row],[firma]],firmy_MK!A4,Tabulka1[[#This Row],[částka na faktuře]]*firmy_MK!C4)} -> #N/A | J5: =WEEKDAY(Tabulka1[[#This Row],[datum uhrazení faktury]],2) -> 1
A6: Firma A | B6: 38720 | C6: =EDATE(Tabulka1[[#This Row],[datum vystavení faktury]],1) -> 38751 | D6: 38768 | E6: =_xlfn.DAYS(Tabulka1[[#This Row],[datum uhrazení faktury]],Tabulka1[[#This Row],[datum splatnosti faktury]]) -> 17 | F6: 114438.98 | G6: 114438.98 | H6: =Tabulka1[[#This Row],[částka na faktuře]] - Tabulka1[[#This Row],[skutečně uhrazeno]] -> 0 | I6: {=_xlfn.SWITCH(Tabulka1[[#This Row],[firma]],firmy_MK!A5,Tabulka1[[#This Row],[částka na faktuře]]*firmy_MK!C5)} -> #N/A | J6: =WEEKDAY(Tabulka1[[#This Row],[datum uhrazení faktury]],2) -> 1
A7: Firma A | B7: 38720 | C7: =EDATE(Tabulka1[[#This Row],[datum vystavení faktury]],1) -> 38751 | D7: 38730 | E7: =_xlfn.DAYS(Tabulka1[[#This Row],[datum uhrazení faktury]],Tabulka1[[#This Row],[datum splatnosti faktury]]) -> -21 | F7: 228311.43 | G7: 228311.43 | H7: =Tabulka1[[#This Row],[částka na faktuře]] - Tabulka1[[#This Row],[skutečně uhrazeno]] -> 0 | I7: {=_xlfn.SWITCH(Tabulka1[[#This Row],[firma]],firmy_MK!A6,Tabulka1[[#This Row],[částka na faktuře]]*firmy_MK!C6)} -> #N/A | J7: =WEEKDAY(Tabulka1[[#This Row],[datum uhrazení faktury]],2) -> 5
A8: Firma A | B8: 38722 | C8: =EDATE(Tabulka1[[#This Row],[datum vystavení faktury]],1) -> 38753 | D8: 38777 | E8: =_xlfn.DAYS(Tabulka1[[#This Row],[datum uhrazení faktury]],Tabulka1[[#This Row],[datum splatnosti faktury]]) -> 24 | F8: 1116.54 | G8: 1116.54 | H8: =Tabulka1[[#This Row],[částka na faktuře]] - Tabulka1[[#This Row],[skutečně uhrazeno]] -> 0 | I8: {=_xlfn.SWITCH(Tabulka1[[#This Row],[firma]],firmy_MK!A7,Tabulka1[[#This Row],[částka na faktuře]]*firmy_MK!C7)} -> #N/A | J8: =WEEKDAY(Tabulka1[[#This Row],[datum uhrazení faktury]],2) -> 3
A9: Firma A | B9: 38723 | C9: =EDATE(Tabulka1[[#This Row],[datum vystavení faktury]],1) -> 38754 | D9: 38786 | E9: =_xlfn.DAYS(Tabulka1[[#This Row],[datum uhrazení faktury]],Tabulka1[[#This Row],[datum splatnosti faktury]]) -> 32 | F9: 159774.41 | G9: 159774.41 | H9: =Tabulka1[[#This Row],[částka na faktuře]] - Tabulka1[[#This Row],[skutečně uhrazeno]] -> 0 | I9: {=_xlfn.SWITCH(Tabulka1[[#This Row],[firma]],firmy_MK!A8,Tabulka1[[#This Row],[částka na faktuře]]*firmy_MK!C8)} -> #N/A | J9: =WEEKDAY(Tabulka1[[#This Row],[datum uhrazení faktury]],2) -> 5
A10: Firma A | B10: 38723 | C10: =EDATE(Tabulka1[[#This Row],[datum vystavení faktury]],1) -> 38754 | D10: 38783 | E10: =_xlfn.DAYS(Tabulka1[[#This Row],[datum uhrazení faktury]],Tabulka1[[#This Row],[datum splatnosti faktury]]) -> 29 | F10: 207461.92 | G10: 207461.92 | H10: =Tabulka1[[#This Row],[částka na faktuře]] - Tabulka1[[#This Row],[skutečně uhrazeno]] -> 0 | I10: {=_xlfn.SWITCH(Tabulka1[[#This Row],[firma]],firmy_MK!A9,Tabulka1[[#This Row],[částka na faktuře]]*firmy_MK!C9)} -> #N/A | J10: =WEEKDAY(Tabulka1[[#This Row],[datum uhrazení faktury]],2) -> 2
A11: Firma A | B11: 38726 | C11: =EDATE(Tabulka1[[#This Row],[datum vystavení faktury]],1) -> 38757 | D11: 38740 | E11: =_xlfn.DAYS(Tabulka1[[#This Row],[datum uhrazení faktury]],Tabulka1[[#This Row],[datum splatnosti faktury]]) -> -17 | F11: 147516.18 | G11: 147516.18 | H11: =Tabulka1[[#This Row],[částka na faktuře]] - Tabulka1[[#This Row],[skutečně uhrazeno]] -> 0 | I11: {=_xlfn.SWITCH(Tabulka1[[#This Row],[firma]],firmy_MK!A10,Tabulka1[[#This Row],[částka na faktuře]]*firmy_MK!C10)} -> #N/A | J11: =WEEKDAY(Tabulka1[[#This Row],[datum uhrazení faktury]],2) -> 1
A12: Firma A | B12: 38727 | C12: =EDATE(Tabulka1[[#This Row],[datum vystavení faktury]],1) -> 38758 | D12: 38748 | E12: =_xlfn.DAYS(Tabulka1[[#This Row],[datum uhrazení faktury]],Tabulka1[[#This Row],[datum splatnosti faktury]]) -> -10 | F12: 139274.4 | G12: 139274.4 | H12: =Tabulka1[[#This Row],[částka na faktuře]] - Tabulka1[[#This Row],[skutečně uhrazeno]] -> 0 | I12: {=_xlfn.SWITCH(Tabulka1[[#This Row],[firma]],firmy_MK!A11,Tabulka1[[#This Row],[částka na faktuře]]*firmy_MK!C11)} -> #N/A | J12: =WEEKDAY(Tabulka1[[#This Row],[datum uhrazení faktury]],2) -> 2
A13: Firma A | B13: 38728 | C13: =EDATE(Tabulka1[[#This Row],[datum vystavení faktury]],1) -> 38759 | D13: 38772 | E13: =_xlfn.DAYS(Tabulka1[[#This Row],[datum uhrazení faktury]],Tabulka1[[#This Row],[datum splatnosti faktury]]) -> 13 | F13: 268911.31 | G13: 268911.31 | H13: =Tabulka1[[#This Row],[částka na faktuře]] - Tabulka1[[#This Row],[skutečně uhrazeno]] -> 0 | I13: {=_xlfn.SWITCH(Tabulka1[[#This Row],[firma]],firmy_MK!A12,Tabulka1[[#This Row],[částka na faktuře]]*firmy_MK!C12)} -> #N/A | J13: =WEEKDAY(Tabulka1[[#This Row],[datum uhrazení faktury]],2) -> 5
... A45: Firma A | B45: 38772 | C45: =EDATE(Tabulka1[[#This Row],[datum vystavení faktury]],1) -> 38800 | D45: 38847 | E45: =_xlfn.DAYS(Tabulka1[[#This Row],[datum uhrazení faktury]],Tabulka1[[#This Row],[datum splatnosti faktury]]) -> 47 | F45: 66767.44 | G45: 66767.44 | H45: =Tabulka1[[#This Row],[částka na faktuře]] - Tabulka1[[#This Row],[skutečně uhrazeno]] -> 0 | I45: {=_xlfn.SWITCH(Tabulka1[[#This Row],[firma]],firmy_MK!A44,Tabulka1[[#This Row],[částka na faktuře]]*firmy_MK!C44)} -> #N/A | J45: =WEEKDAY(Tabulka1[[#This Row],[datum uhrazení faktury]],2) -> 3
A46: Firma A | B46: 38776 | C46: =EDATE(Tabulka1[[#This Row],[datum vystavení faktury]],1) -> 38804 | E46: =_xlfn.DAYS(Tabulka1[[#This Row],[datum uhrazení faktury]],Tabulka1[[#This Row],[datum splatnosti faktury]]) -> #VALUE! | F46: 206622 | H46: =Tabulka1[[#This Row],[částka na faktuře]] - Tabulka1[[#This Row],[skutečně uhrazeno]] -> 206622 | I46: {=_xlfn.SWITCH(Tabulka1[[#This Row],[firma]],firmy_MK!A45,Tabulka1[[#This Row],[částka na faktuře]]*firmy_MK!C45)} -> #N/A | J46: =WEEKDAY(Tabulka1[[#This Row],[datum uhrazení faktury]],2) -> #VALUE!
A47: Firma A | B47: 38777 | C47: =EDATE(Tabulka1[[#This Row],[datum vystavení faktury]],1) -> 38808 | D47: 38842 | E47: =_xlfn.DAYS(Tabulka1[[#This Row],[datum uhrazení faktury]],Tabulka1[[#This Row],[datum splatnosti faktury]]) -> 34 | F47: 233316.99 | G47: 233316.99 | H47: =Tabulka1[[#This Row],[částka na faktuře]] - Tabulka1[[#This Row],[skutečně uhrazeno]] -> 0 | I47: {=_xlfn.SWITCH(Tabulka1[[#This Row],[firma]],firmy_MK!A46,Tabulka1[[#This Row],[částka na faktuře]]*firmy_MK!C46)} -> #N/A | J47: =WEEKDAY(Tabulka1[[#This Row],[datum uhrazení faktury]],2) -> 5
A48: Firma A | B48: 38779 | C48: =EDATE(Tabulka1[[#This Row],[datum vystavení faktury]],1) -> 38810 | D48: 38818 | E48: =_xlfn.DAYS(Tabulka1[[#This Row],[datum uhrazení faktury]],Tabulka1[[#This Row],[datum splatnosti faktury]]) -> 8 | F48: 164888.68 | G48: 164888.68 | H48: =Tabulka1[[#This Row],[částka na faktuře]] - Tabulka1[[#This Row],[skutečně uhrazeno]] -> 0 | I48: {=_xlfn.SWITCH(Tabulka1[[#This Row],[firma]],firmy_MK!A47,Tabulka1[[#This Row],[částka na faktuře]]*firmy_MK!C47)} -> #N/A | J48: =WEEKDAY(Tabulka1[[#This Row],[datum uhrazení faktury]],2) -> 2
A49: Firma A | B49: 38779 | C49: =EDATE(Tabulka1[[#This Row],[datum vystavení faktury]],1) -> 38810 | D49: 38840 | E49: =_xlfn.DAYS(Tabulka1[[#This Row],[datum uhrazení faktury]],Tabulka1[[#This Row],[datum splatnosti faktury]]) -> 30 | F49: 80721.72 | G49: 80721.72 | H49: =Tabulka1[[#This Row],[částka na faktuře]] - Tabulka1[[#This Row],[skutečně uhrazeno]] -> 0 | I49: {=_xlfn.SWITCH(Tabulka1[[#This Row],[firma]],firmy_MK!A48,Tabulka1[[#This Row],[částka na faktuře]]*firmy_MK!C48)} -> #N/A | J49: =WEEKDAY(Tabulka1[[#This Row],[datum uhrazení faktury]],2) -> 3
A50: Firma A | B50: 38779 | C50: =EDATE(Tabulka1[[#This Row],[datum vystavení faktury]],1) -> 38810 | E50: =_xlfn.DAYS(Tabulka1[[#This Row],[datum uhrazení faktury]],Tabulka1[[#This Row],[datum splatnosti faktury]]) -> #VALUE! | F50: 70044.41 | H50: =Tabulka1[[#This Row],[částka na faktuře]] - Tabulka1[[#This Row],[skutečně uhrazeno]] -> 70044.41 | I50: {=_xlfn.SWITCH(Tabulka1[[#This Row],[firma]],firmy_MK!A49,Tabulka1[[#This Row],[částka na faktuře]]*firmy_MK!C49)} -> #N/A | J50: =WEEKDAY(Tabulka1[[#This Row],[datum uhrazení faktury]],2) -> #VALUE!
A51: Firma A | B51: 38782 | C51: =EDATE(Tabulka1[[#This Row],[datum vystavení faktury]],1) -> 38813 | D51: 38820 | E51: =_xlfn.DAYS(Tabulka1[[#This Row],[datum uhrazení faktury]],Tabulka1[[#This Row],[datum splatnosti faktury]]) -> 7 | F51: 269161.72 | G51: 269161.72 | H51: =Tabulka1[[#This Row],[částka na faktuře]] - Tabulka1[[#This Row],[skutečně uhrazeno]] -> 0 | I51: {=_xlfn.SWITCH(Tabulka1[[#This Row],[firma]],firmy_MK!A50,Tabulka1[[#This Row],[částka na faktuře]]*firmy_MK!C50)} -> #N/A | J51: =WEEKDAY(Tabulka1[[#This Row],[datum uhrazení faktury]],2) -> 4
A52: Firma A | B52: 38783 | C52: =EDATE(Tabulka1[[#This Row],[datum vystavení faktury]],1) -> 38814 | D52: 38841 | E52: =_xlfn.DAYS(Tabulka1[[#This Row],[datum uhrazení faktury]],Tabulka1[[#This Row],[datum splatnosti faktury]]) -> 27 | F52: 156268.55 | G52: 156268.55 | H52: =Tabulka1[[#This Row],[částka na faktuře]] - Tabulka1[[#This Row],[skutečně uhrazeno]] -> 0 | I52: {=_xlfn.SWITCH(Tabulka1[[#This Row],[firma]],firmy_MK!A51,Tabulka1[[#This Row],[částka na faktuře]]*firmy_MK!C51)} -> #N/A | J52: =WEEKDAY(Tabulka1[[#This Row],[datum uhrazení faktury]],2) -> 4
A53: Firma A | B53: 38784 | C53: =EDATE(Tabulka1[[#This Row],[datum vystavení faktury]],1) -> 38815 | D53: 38833 | E53: =_xlfn.DAYS(Tabulka1[[#This Row],[datum uhrazení faktury]],Tabulka1[[#This Row],[datum splatnosti faktury]]) -> 18 | F53: 77461.63 | G53: 77461.63 | H53: =Tabulka1[[#This Row],[částka na faktuře]] - Tabulka1[[#This Row],[skutečně uhrazeno]] -> 0 | I53: {=_xlfn.SWITCH(Tabulka1[[#This Row],[firma]],firmy_MK!A52,Tabulka1[[#This Row],[částka na faktuře]]*firmy_MK!C52)} -> #N/A | J53: =WEEKDAY(Tabulka1[[#This Row],[datum uhrazení faktury]],2) -> 3
A54: Firma A | B54: 38784 | C54: =EDATE(Tabulka1[[#This Row],[datum vystavení faktury]],1) -> 38815 | D54: 38832 | E54: =_xlfn.DAYS(Tabulka1[[#This Row],[datum uhrazení faktury]],Tabulka1[[#This Row],[datum splatnosti faktury]]) -> 17 | F54: 213092.14 | G54: 213092.14 | H54: =Tabulka1[[#This Row],[částka na faktuře]] - Tabulka1[[#This Row],[skutečně uhrazeno]] -> 0 | I54: {=_xlfn.SWITCH(Tabulka1[[#This Row],[firma]],firmy_MK!A53,Tabulka1[[#This Row],[částka na faktuře]]*firmy_MK!C53)} -> #N/A | J54: =WEEKDAY(Tabulka1[[#This Row],[datum uhrazení faktury]],2) -> 2
A55: Firma A | B55: 38785 | C55: =EDATE(Tabulka1[[#This Row],[datum vystavení faktury]],1) -> 38816 | E55: =_xlfn.DAYS(Tabulka1[[#This Row],[datum uhrazení faktury]],Tabulka1[[#This Row],[datum splatnosti faktury]]) -> #VALUE! | F55: 77242.18 | H55: =Tabulka1[[#This Row],[částka na faktuře]] - Tabulka1[[#This Row],[skutečně uhrazeno]] -> 77242.18 | I55: {=_xlfn.SWITCH(Tabulka1[[#This Row],[firma]],firmy_MK!A54,Tabulka1[[#This Row],[částka na faktuře]]*firmy_MK!C54)} -> #N/A | J55: =WEEKDAY(Tabulka1[[#This Row],[datum uhrazení faktury]],2) -> #VALUE!
A56: Firma A | B56: 38790 | C56: =EDATE(Tabulka1[[#This Row],[datum vystavení faktury]],1) -> 38821 | E56: =_xlfn.DAYS(Tabulka1[[#This Row],[datum uhrazení faktury]],Tabulka1[[#This Row],[datum splatnosti faktury]]) -> #VALUE! | F56: 162225.67 | H56: =Tabulka1[[#This Row],[částka na faktuře]] - Tabulka1[[#This Row],[skutečně uhrazeno]] -> 162225.67 | I56: {=_xlfn.SWITCH(Tabulka1[[#This Row],[firma]],firmy_MK!A55,Tabulka1[[#This Row],[částka na faktuře]]*firmy_MK!C55)} -> #N/A | J56: =WEEKDAY(Tabulka1[[#This Row],[datum uhrazení faktury]],2) -> #VALUE!
A57: Firma A | B57: 38793 | C57: =EDATE(Tabulka1[[#This Row],[datum vystavení faktury]],1) -> 38824 | D57: 38821 | E57: =_xlfn.DAYS(Tabulka1[[#This Row],[datum uhrazení faktury]],Tabulka1[[#This Row],[datum splatnosti faktury]]) -> -3 | F57: 12257.99 | G57: 12257.99 | H57: =Tabulka1[[#This Row],[částka na faktuře]] - Tabulka1[[#This Row],[skutečně uhrazeno]] -> 0 | I57: {=_xlfn.SWITCH(Tabulka1[[#This Row],[firma]],firmy_MK!A56,Tabulka1[[#This Row],[částka na faktuře]]*firmy_MK!C56)} -> #N/A | J57: =WEEKDAY(Tabulka1[[#This Row],[datum uhrazení faktury]],2) -> 5
A58: Firma A | B58: 38793 | C58: =EDATE(Tabulka1[[#This Row],[datum vystavení faktury]],1) -> 38824 | E58: =_xlfn.DAYS(Tabulka1[[#This Row],[datum uhrazení faktury]],Tabulka1[[#This Row],[datum splatnosti faktury]]) -> #VALUE! | F58: 232256.06 | H58: =Tabulka1[[#This Row],[částka na faktuře]] - Tabulka1[[#This Row],[skutečně uhrazeno]] -> 232256.06 | I58: {=_xlfn.SWITCH(Tabulka1[[#This Row],[firma]],firmy_MK!A57,Tabulka1[[#This Row],[částka na faktuře]]*firmy_MK!C57)} -> #N/A | J58: =WEEKDAY(Tabulka1[[#This Row],[datum uhrazení faktury]],2) -> #VALUE!
A59: Firma A | B59: 38793 | C59: =EDATE(Tabulka1[[#This Row],[datum vystavení faktury]],1) -> 38824 | D59: 38821 | E59: =_xlfn.DAYS(Tabulka1[[#This Row],[datum uhrazení faktury]],Tabulka1[[#This Row],[datum splatnosti faktury]]) -> -3 | F59: 147622.05 | G59: 147622.05 | H59: =Tabulka1[[#This Row],[částka na faktuře]] - Tabulka1[[#This Row],[skutečně uhrazeno]] -> 0 | I59: {=_xlfn.SWITCH(Tabulka1[[#This Row],[firma]],firmy_MK!A58,Tabulka1[[#This Row],[částka na faktuře]]*firmy_MK!C58)} -> #N/A | J59: =WEEKDAY(Tabulka1[[#This Row],[datum uhrazení faktury]],2) -> 5
A60: Firma A | B60: 38797 | C60: =EDATE(Tabulka1[[#This Row],[datum vystavení faktury]],1) -> 38828 | D60: 38800 | E60: =_xlfn.DAYS(Tabulka1[[#This Row],[datum uhrazení faktury]],Tabulka1[[#This Row],[datum splatnosti faktury]]) -> -28 | F60: 72791.85 | G60: 72791.85 | H60: =Tabulka1[[#This Row],[částka na faktuře]] - Tabulka1[[#This Row],[skutečně uhrazeno]] -> 0 | I60: {=_xlfn.SWITCH(Tabulka1[[#This Row],[firma]],firmy_MK!A59,Tabulka1[[#This Row],[částka na faktuře]]*firmy_MK!C59)} -> #N/A | J60: =WEEKDAY(Tabulka1[[#This Row],[datum uhrazení faktury]],2) -> 5
A61: Firma A | B61: 38798 | C61: =EDATE(Tabulka1[[#This Row],[datum vystavení faktury]],1) -> 38829 | E61: =_xlfn.DAYS(Tabulka1[[#This Row],[datum uhrazení faktury]],Tabulka1[[#This Row],[datum splatnosti faktury]]) -> #VALUE! | F61: 9593.83 | H61: =Tabulka1[[#This Row],[částka na faktuře]] - Tabulka1[[#This Row],[skutečně uhrazeno]] -> 9593.83 | I61: {=_xlfn.SWITCH(Tabulka1[[#This Row],[firma]],firmy_MK!A60,Tabulka1[[#This Row],[částka na faktuře]]*firmy_MK!C60)} -> #N/A | J61: =WEEKDAY(Tabulka1[[#This Row],[datum uhrazení faktury]],2) -> #VALUE!
A62: Firma A | B62: 38799 | C62: =EDATE(Tabulka1[[#This Row],[datum vystavení faktury]],1) -> 38830 | E62: =_xlfn.DAYS(Tabulka1[[#This Row],[datum uhrazení faktury]],Tabulka1[[#This Row],[datum splatnosti faktury]]) -> #VALUE! | F62: 261939.42 | H62: =Tabulka1[[#This Row],[částka na faktuře]] - Tabulka1[[#This Row],[skutečně uhrazeno]] -> 261939.42 | I62: {=_xlfn.SWITCH(Tabulka1[[#This Row],[firma]],firmy_MK!A61,Tabulka1[[#This Row],[částka na faktuře]]*firmy_MK!C61)} -> #N/A | J62: =WEEKDAY(Tabulka1[[#This Row],[datum uhrazení faktury]],2) -> #VALUE!
A63: Firma A | B63: 38799 | C63: =EDATE(Tabulka1[[#This Row],[datum vystavení faktury]],1) -> 38830 | E63: =_xlfn.DAYS(Tabulka1[[#This Row],[datum uhrazení faktury]],Tabulka1[[#This Row],[datum splatnosti faktury]]) -> #VALUE! | F63: 44748.51 | H63: =Tabulka1[[#This Row],[částka na faktuře]] - Tabulka1[[#This Row],[skutečně uhrazeno]] -> 44748.51 | I63: {=_xlfn.SWITCH(Tabulka1[[#This Row],[firma]],firmy_MK!A62,Tabulka1[[#This Row],[částka na faktuře]]*firmy_MK!C62)} -> #N/A | J63: =WEEKDAY(Tabulka1[[#This Row],[datum uhrazení faktury]],2) -> #VALUE!
A64: Firma A | B64: 38800 | C64: =EDATE(Tabulka1[[#This Row],[datum vystavení faktury]],1) -> 38831 | D64: 38799 | E64: =_xlfn.DAYS(Tabulka1[[#This Row],[datum uhrazení faktury]],Tabulka1[[#This Row],[datum splatnosti faktury]]) -> -32 | F64: 156422.11 | G64: 156422.11 | H64: =Tabulka1[[#This Row],[částka na faktuře]] - Tabulka1[[#This Row],[skutečně uhrazeno]] -> 0 | I64: {=_xlfn.SWITCH(Tabulka1[[#This Row],[firma]],firmy_MK!A63,Tabulka1[[#This Row],[částka na faktuře]]*firmy_MK!C63)} -> #N/A | J64: =WEEKDAY(Tabulka1[[#This Row],[datum uhrazení faktury]],2) -> 4
A65: Firma A | B65: 38800 | C65: =EDATE(Tabulka1[[#This Row],[datum vystavení faktury]],1) -> 38831 | E65: =_xlfn.DAYS(Tabulka1[[#This Row],[datum uhrazení faktury]],Tabulka1[[#This Row],[datum splatnosti faktury]]) -> #VALUE! | F65: 146860.45 | H65: =Tabulka1[[#This Row],[částka na faktuře]] - Tabulka1[[#This Row],[skutečně uhrazeno]] -> 146860.45 | I65: {=_xlfn.SWITCH(Tabulka1[[#This Row],[firma]],firmy_MK!A64,Tabulka1[[#This Row],[částka na faktuře]]*firmy_MK!C64)} -> #N/A | J65: =WEEKDAY(Tabulka1[[#This Row],[datum uhrazení faktury]],2) -> #VALUE!
A66: Firma A | B66: 38803 | C66: =EDATE(Tabulka1[[#This Row],[datum vystavení faktury]],1) -> 38834 | D66: 38847 | E66: =_xlfn.DAYS(Tabulka1[[#This Row],[datum uhrazení faktury]],Tabulka1[[#This Row],[datum splatnosti faktury]]) -> 13 | F66: 222520.67 | G66: 222520.67 | H66: =Tabulka1[[#This Row],[částka na faktuře]] - Tabulka1[[#This Row],[skutečně uhrazeno]] -> 0 | I66: {=_xlfn.SWITCH(Tabulka1[[#This Row],[firma]],firmy_MK!A65,Tabulka1[[#This Row],[částka na faktuře]]*firmy_MK!C65)} -> #N/A | J66: =WEEKDAY(Tabulka1[[#This Row],[datum uhrazení faktury]],2) -> 3
A67: Firma A | B67: 38803 | C67: =EDATE(Tabulka1[[#This Row],[datum vystavení faktury]],1) -> 38834 | E67: =_xlfn.DAYS(Tabulka1[[#This Row],[datum uhrazení faktury]],Tabulka1[[#This Row],[datum splatnosti faktury]]) -> #VALUE! | F67: 93879.28 | H67: =Tabulka1[[#This Row],[částka na faktuře]] - Tabulka1[[#This Row],[skutečně uhrazeno]] -> 93879.28 | I67: {=_xlfn.SWITCH(Tabulka1[[#This Row],[firma]],firmy_MK!A66,Tabulka1[[#This Row],[částka na faktuře]]*firmy_MK!C66)} -> #N/A | J67: =WEEKDAY(Tabulka1[[#This Row],[datum uhrazení faktury]],2) -> #VALUE!
A68: Firma A | B68: 38804 | C68: =EDATE(Tabulka1[[#This Row],[datum vystavení faktury]],1) -> 38835 | D68: 38849 | E68: =_xlfn.DAYS(Tabulka1[[#This Row],[datum uhrazení faktury]],Tabulka1[[#This Row],[datum splatnosti faktury]]) -> 14 | F68: 63888.86 | G68: 63888.86 | H68: =Tabulka1[[#This Row],[částka na faktuře]] - Tabulka1[[#This Row],[skutečně uhrazeno]] -> 0 | I68: {=_xlfn.SWITCH(Tabulka1[[#This Row],[firma]],firmy_MK!A67,Tabulka1[[#This Row],[částka na faktuře]]*firmy_MK!C67)} -> #N/A | J68: =WEEKDAY(Tabulka1[[#This Row],[datum uhrazení faktury]],2) -> 5
A69: Firma A | B69: 38804 | C69: =EDATE(Tabulka1[[#This Row],[datum vystavení faktury]],1) -> 38835 | E69: =_xlfn.DAYS(Tabulka1[[#This Row],[datum uhrazení faktury]],Tabulka1[[#This Row],[datum splatnosti faktury]]) -> #VALUE! | F69: 109497.07 | H69: =Tabulka1[[#This Row],[částka na faktuře]] - Tabulka1[[#This Row],[skutečně uhrazeno]] -> 109497.07 | I69: {=_xlfn.SWITCH(Tabulka1[[#This Row],[firma]],firmy_MK!A68,Tabulka1[[#This Row],[částka na faktuře]]*firmy_MK!C68)} -> #N/A | J69: =WEEKDAY(Tabulka1[[#This Row],[datum uhrazení faktury]],2) -> #VALUE!
A70: Firma A | B70: 38806 | C70: =EDATE(Tabulka1[[#This Row],[datum vystavení faktury]],1) -> 38837 | E70: =_xlfn.DAYS(Tabulka1[[#This Row],[datum uhrazení faktury]],Tabulka1[[#This Row],[datum splatnosti faktury]]) -> #VALUE! | F70: 256623.26 | H70: =Tabulka1[[#This Row],[částka na faktuře]] - Tabulka1[[#This Row],[skutečně uhrazeno]] -> 256623.26 | I70: {=_xlfn.SWITCH(Tabulka1[[#This Row],[firma]],firmy_MK!A69,Tabulka1[[#This Row],[částka na faktuře]]*firmy_MK!C69)} -> #N/A | J70: =WEEKDAY(Tabulka1[[#This Row],[datum uhrazení faktury]],2) -> #VALUE!
A71: Firma A | B71: 38810 | C71: =EDATE(Tabulka1[[#This Row],[datum vystavení faktury]],1) -> 38840 | D71: 38835 | E71: =_xlfn.DAYS(Tabulka1[[#This Row],[datum uhrazení faktury]],Tabulka1[[#This Row],[datum splatnosti faktury]]) -> -5 | F71: 248380.51 | G71: 248380.51 | H71: =Tabulka1[[#This Row],[částka na faktuře]] - Tabulka1[[#This Row],[skutečně uhrazeno]] -> 0 | I71: {=_xlfn.SWITCH(Tabulka1[[#This Row],[firma]],firmy_MK!A70,Tabulka1[[#This Row],[částka na faktuře]]*firmy_MK!C70)} -> #N/A | J71: =WEEKDAY(Tabulka1[[#This Row],[datum uhrazení faktury]],2) -> 5
...

Sheet firmy_MK
A1: Firma A | B1: USD | C1: =IF(B1="USD",$G$1,$G$2) -> 25.15 | F1: aktuální kurz USD: | G1: 25.15
A2: Firma B | B2: EUR | C2: =IF(B2="USD",$G$1,$G$2) -> 27.25 | F2: aktuální kurz EUR: | G2: 27.25
A3: Firma C | B3: EUR | C3: =IF(B3="USD",$G$1,$G$2) -> 27.25
A4: Firma D | B4: USD | C4: =IF(B4="USD",$G$1,$G$2) -> 25.15
A5: Firma E | B5: EUR | C5: =IF(B5="USD",$G$1,$G$2) -> 27.25
A6: Firma F | B6: USD | C6: =IF(B6="USD",$G$1,$G$2) -> 25.15
A7: Firma G | B7: EUR | C7: =IF(B7="USD",$G$1,$G$2) -> 27.25
A8: Firma H | B8: USD | C8: =IF(B8="USD",$G$1,$G$2) -> 25.15
A9: Firma I | B9: EUR | C9: =IF(B9="USD",$G$1,$G$2) -> 27.25
A10: Firma J | B10: USD | C10: =IF(B10="USD",$G$1,$G$2) -> 25.15
A11: Firma K | B11: EUR | C11: =IF(B11="USD",$G$1,$G$2) -> 27.25
A12: Firma L | B12: USD | C12: =IF(B12="USD",$G$1,$G$2) -> 25.15
A13: Firma M | B13: USD | C13: =IF(B13="USD",$G$1,$G$2) -> 25.15
A14: Firma N | B14: EUR | C14: =IF(B14="USD",$G$1,$G$2) -> 27.25
... A26: Firma Z | B26: USD | C26: =IF(B26="USD",$G$1,$G$2) -> 25.15

Sheet Grafy funkcí
A2: x | B2: y | D2: a | E2: b | F2: c
A3: -10 | B3: =$D$3*$A3^2+$E$3*$A3+$F$3 -> 63 | D3: 1 | E3: 4 | F3: 3
A4: -9.5 | B4: =$D$3*$A4^2+$E$3*$A4+$F$3 -> 55.25
A5: -9 | B5: =$D$3*$A5^2+$E$3*$A5+$F$3 -> 48
A6: -8.5 | B6: =$D$3*$A6^2+$E$3*$A6+$F$3 -> 41.25
A7: -8 | B7: =$D$3*$A7^2+$E$3*$A7+$F$3 -> 35
A8: -7.5 | B8: =$D$3*$A8^2+$E$3*$A8+$F$3 -> 29.25
A9: -7 | B9: =$D$3*$A9^2+$E$3*$A9+$F$3 -> 24
A10: -6.5 | B10: =$D$3*$A10^2+$E$3*$A10+$F$3 -> 19.25
A11: -6 | B11: =$D$3*$A11^2+$E$3*$A11+$F$3 -> 15
A12: -5.5 | B12: =$D$3*$A12^2+$E$3*$A12+$F$3 -> 11.25
A13: -5 | B13: =$D$3*$A13^2+$E$3*$A13+$F$3 -> 8
A14: -4.5 | B14: =$D$3*$A14^2+$E$3*$A14+$F$3 -> 5.25
A15: -4 | B15: =$D$3*$A15^2+$E$3*$A15+$F$3 -> 3
... A43: 10 | B43: =$D$3*$A43^2+$E$3*$A43+$F$3 -> 143

Sheet Burzovní_graf
B1: Devizy | G1: Valuty
A2: Datum | B2: Nákup | C2: Prodej | D2: Střed | E2: Střed | F2: Objemy | G2: Nákup | H2: Prodej
A3: 2.11.2010 | B3: 24.056 | C3: 24.988 | D3: 24.522 | E3: =VALUE(REPLACE(D3,SEARCH(".",D3,1),1,",")) -> #VALUE! | F3: 8923259 | G3: 23.931 | H3: 25.111
A4: 1.11.2010 | B4: 23.983 | C4: 25.062 | D4: 24.522 | E4: =VALUE(REPLACE(D4,SEARCH(".",D4,1),1,",")) -> #VALUE! | F4: 4946306 | G4: 23.931 | H4: 25.111
A5: 29.10.2010 | B5: 24.072 | C5: 25.155 | D5: 24.614 | E5: =VALUE(REPLACE(D5,SEARCH(".",D5,1),1,",")) -> #VALUE! | F5: 4948369 | G5: 24.021 | H5: 25.204
A6: 27.10.2010 | B6: 24.095 | C6: 25.255 | D6: 24.675 | E6: =VALUE(REPLACE(D6,SEARCH(".",D6,1),1,",")) -> #VALUE! | F6: 8124222 | G6: 24.080 | H6: 25.267
A7: 26.10.2010 | B7: 24.078 | C7: 25.162 | D7: 24.62 | E7: =VALUE(REPLACE(D7,SEARCH(".",D7,1),1,",")) -> #VALUE! | F7: 4239561 | G7: 24.027 | H7: 25.211
A8: 25.10.2010 | B8: 23.957 | C8: 25.034 | D8: 24.496 | E8: =VALUE(REPLACE(D8,SEARCH(".",D8,1),1,",")) -> #VALUE! | F8: 5299398 | G8: 23.905 | H8: 25.083
A9: 22.10.2010 | B9: 24.026 | C9: 25.107 | D9: 24.566 | E9: =VALUE(REPLACE(D9,SEARCH(".",D9,1),1,",")) -> #VALUE! | F9: 6485527 | G9: 23.974 | H9: 25.156
A10: 21.10.2010 | B10: 24.038 | C10: 25.119 | D10: 24.579 | E10: =VALUE(REPLACE(D10,SEARCH(".",D10,1),1,",")) -> #VALUE! | F10: 7772129 | G10: 23.986 | H10: 25.169
A11: 20.10.2010 | B11: 23.976 | C11: 25.055 | D11: 24.515 | E11: =VALUE(REPLACE(D11,SEARCH(".",D11,1),1,",")) -> #VALUE! | F11: 5434513 | G11: 23.924 | H11: 25.104
A12: 19.10.2010 | B12: 24.002 | C12: 25.082 | D12: 24.542 | E12: =VALUE(REPLACE(D12,SEARCH(".",D12,1),1,",")) -> #VALUE! | F12: 3518027 | G12: 23.951 | H12: 25.131
A13: 18.10.2010 | B13: 23.983 | C13: 25.061 | D13: 24.522 | E13: =VALUE(REPLACE(D13,SEARCH(".",D13,1),1,",")) -> #VALUE! | F13: 6417453 | G13: 23.931 | H13: 25.110
A14: 15.10.2010 | B14: 23.985 | C14: 25.065 | D14: 24.525 | E14: =VALUE(REPLACE(D14,SEARCH(".",D14,1),1,",")) -> #VALUE! | F14: 4746453 | G14: 23.934 | H14: 25.114
... A22: 5.10.2010 | B22: 23.956 | C22: 25.034 | D22: 24.495 | E22: =VALUE(REPLACE(D22,SEARCH(".",D22,1),1,",")) -> #VALUE! | F22: 3780112 | G22: 23.905 | H22: 25.083

Sheet Kdo má dnes svátek
A1: Kdo má dnes svátek
B4: Dnes má svátek | D4: {=_xlfn.XLOOKUP(C5,Q10:AB10,_xlfn.ANCHORARRAY(Q11))} -> Alexandra | F4: =B4&" "&D4 -> Dnes má svátek Alexandra
B5: =DAY(TODAY()) -> 21 | C5: =MONTH(TODAY()) -> 4
A9: Datum | B9: Leden | C9: Únor | D9: Březen | E9: Duben | F9: Květen | G9: Červen | H9: Červenec | I9: Srpen | J9: Září | K9: Říjen | L9: Listopad | M9: Prosinec
A10: 1 | B10: Nový rok | C10: Hynek | D10: Bedřich | E10: Hugo | F10: Práce | G10: Laura | H10: Jaroslava | I10: Oskar | J10: Linda, Samuel | K10: Igor | L10: Felix | M10: Iva | Q10: 1 | R10: 2 | S10: 3 | T10: 4 | U10: 5 | V10: 6 | W10: 7 | X10: 8 | Y10: 9 | Z10: 10 | AA10: 11 | AB10: 12
A11: 2 | B11: Karina | C11: Nela | D11: Anežka | E11: Erika | F11: Zikmund | G11: Jarmil | H11: Patricie | I11: Gustav | J11: Adéla | K11: Olívie, Oliver | L11: Zesnulí | M11: Blanka | Q11: {=_xlfn.XLOOKUP(B5,A10:A40,B10:M40)} -> Běla | R11: Lenka | S11: Radek | T11: Alexandra | U11: Monika | V11: Alois | W11: Vítězslav | X11: Johana | Y11: Matouš | Z11: Brigita | AA11: Albert | AB11: Natálie
A12: 3 | B12: Radmila | C12: Blažej | D12: Kamil | E12: Richard | F12: Alexej | G12: Tamara | H12: Radomír | I12: Miluše | J12: Bronislav | K12: Bohumil | L12: Hubert | M12: Svatoslav
A13: 4 | B13: Diana | C13: Jarmila | D13: Stela | E13: Ivana | F13: Květoslav | G13: Dalibor | H13: Prokop | I13: Dominik | J13: Jindřiška | K13: František | L13: Karel | M13: Barbora
A14: 5 | B14: Dalimil | C14: Dobromila | D14: Kazimír | E14: Miroslava | F14: Klaudie | G14: Dobroslav | H14: Cyril, Metoděj | I14: Kristián | J14: Boris | K14: Eliška | L14: Miriam | M14: Jitka
A15: 6 | B15: Kašpar, Melichar, Baltazar | C15: Vanda | D15: Miroslav | E15: Vendula | F15: Radoslav | G15: Norbert | H15: Jan Hus | I15: Oldřiška | J15: Boleslav | K15: Hanuš | L15: Liběna | M15: Mikuláš
A16: 7 | B16: Vilma | C16: Veronika | D16: Tomáš | E16: Heřman, Hermína | F16: Stanislav | G16: Iveta, Slavoj | H16: Mohuslava | I16: Lada | J16: Regina | K16: Justina | L16: ¨Saskie | M16: Ambrož, Benjamin
A17: 8 | B17: Čestmír | C17: Milada | D17: Gabriela | E17: Ema | F17: Česká republika | G17: Medard | H17: Nora | I17: Soběslav | J17: Mariana | K17: Věra | L17: Bohumír | M17: Květoslava
A18: 9 | B18: Vladan | C18: Apolena | D18: Františka | E18: Dušan | F18: Ctibor | G18: Stanislava | H18: Drahoslava | I18: Roman | J18: Daniela | K18: Štefan, Sára | L18: Bohdan | M18: Vratislav
A19: 10 | B19: Břetislav | C19: Mojmír | D19: Viktorie | E19: Darja | F19: Blažena | G19: Gita | H19: Libuše, Amálie | I19: Vavřinec | J19: Irma | K19: Marina | L19: Evžen | M19: Julie
A20: 11 | B20: Bohdana | C20: Božena | D20: Anděla | E20: Izabela | F20: Svatava | G20: Bruno | H20: Olga | I20: Zuzana | J20: Denisa | K20: Andrej | L20: Martin | M20: Dana
A21: 12 | B21: Pravoslav | C21: Slavěna | D21: Řehoř | E21: Julius | F21: Pankrác | G21: Antonie | H21: Bořek | I21: Klára | J21: Marie | K21: Marcel | L21: Benedikt | M21: Simona
A22: 13 | B22: Edita | C22: Věnceslav | D22: Růžena | E22: Aleš | F22: Servác | G22: Antonín | H22: Markéta | I22: Alena | J22: Lubor | K22: Renata | L22: Tibor | M22: Lucie
A23: 14 | B23: Radovan | C23: Valentin | D23: Matylda | E23: Vincenc | F23: Bonifác | G23: Richard | H23: Karolina | I23: Alan | J23: Radka | K23: Agata | L23: Sáva | M23: Lýdie
... A37: 28 | B37: Otýlie | C37: Lumír | D37: Soňa | E37: Vlastislav | F37: Vilém | G37: Lubomír | H37: Viktor | I37: Augustin | J37: Václav | K37: Česká republika | L37: René | M37: Bohumila
A38: 29 | B38: Zdislava | D38: Taťána | E38: Robert | F38: Maxmilián | G38: Petr, Pavel | H38: Marta | I38: Evelina | J38: Michal | K38: Silvie | L38: Zina | M38: Judita
A39: 30 | B39: Robin | D39: Arnošet | E39: Blahoslav | F39: Ferdinand | G39: Šárka | H39: Bořivoj | I39: Vladěna | J39: Jeroným | K39: Tadeáš | L39: Ondřej | M39: David
A40: 31 | B40: Marika | D40: Kvido | F40: Kamila | H40: Ignác | I40: Pavlína | K40: Štěpánka | M40: Silvestr

Sheet morseovka
A1: A | B1: .- | C1: akát
A2: B | B2: -…
A3: C | B3: -.-.
A4: D | B4: -..
A5: E | B5: . | C5: erb
A6: F | B6: ..-.
A7: G | B7: --.
A8: H | B8: ....
A9: Ch | B9: ----
A10: I | B10: ..
A11: J | B11: .---
A12: K | B12: -.-
A13: L | B13: .-..
A14: M | B14: --
A15: N | B15: -.
A16: O | B16: ---
A17: P | B17: .--.
... A19: R | B19: .-.
A20: S | B20: … | C20: sekera
A21: T | B21: - | C21: tón
A22: U | B22: ..-
A23: V | B23: ...- | H23: =SUBSTITUTE(E31," ","") -> TOLIN
A24: W | B24: .--
A25: X | B25: -..- | H25: 1 | I25: 2 | J25: 3 | K25: 4 | L25: 5 | M25: 6 | N25: 7 | O25: 8 | P25: 9 | Q25: 10 | R25: 11 | S25: 12 | T25: 13 | U25: 14 | V25: 15 | W25: 16 | X25: 17 | Y25: 18 | Z25: 19 | AA25: 20 | AB25: 21 | AC25: 22 | AD25: 23 | AE25: 24 | AF25: 25 | AG25: 26 | AH25: 27 | AI25: 28 | AJ25: 29 | AK25: 30 | AL25: 31 | AM25: 32 | AN25: 33 | AO25: 34 | AP25: 35 | AQ25: 36 | AR25: 37 | AS25: 38 | AT25: 39 | AU25: 40 | AV25: 41 | AW25: 42 | AX25: 43 | AY25: 44 | AZ25: 45 | BA25: 46 | BB25: 47 | BC25: 48 | BD25: 49 | BE25: 50
A26: Y | B26: -.-- | H26: =MID($H$23,H25,1) -> T | I26: =MID($H$23,I25,1) -> O | J26: =MID($H$23,J25,1) -> L | K26: =MID($H$23,K25,1) -> I | L26: =MID($H$23,L25,1) -> N | M26: =MID($H$23,M25,1) | N26: =MID($H$23,N25,1) | O26: =MID($H$23,O25,1) | ... BE26: =MID($H$23,BE25,1)
A27: Z | B27: --.. | H27: =IFERROR(VLOOKUP(H26,$A$1:$B$28,2)&"|"," ") -> - | | I27: =IFERROR(VLOOKUP(I26,$A$1:$B$28,2)&"|"," ") -> --- | | J27: =IFERROR(VLOOKUP(J26,$A$1:$B$28,2)&"|"," ") -> .-.. | | K27: =IFERROR(VLOOKUP(K26,$A$1:$B$28,2)&"|"," ") -> .. | | L27: =IFERROR(VLOOKUP(L26,$A$1:$B$28,2)&"|"," ") -> -. | | M27: =IFERROR(VLOOKUP(M26,$A$1:$B$28,2)&"|"," ") | N27: =IFERROR(VLOOKUP(N26,$A$1:$B$28,2)&"|"," ") | O27: =IFERROR(VLOOKUP(O26,$A$1:$B$28,2)&"|"," ") | ... BE27: =IFERROR(VLOOKUP(BE26,$A$1:$B$28,2)&"|"," ")
D30: vstupní zpráva
E31: TOLIN | G31: výstup: | H31: =_xlfn.CONCAT(H27:BE27) -> - | --- | .-.. | .. | -. |

Sheet Makra_VBA
A1: 1) Vytvořte makro1, které bude na aktivním listu vkládat do oblasti A1:G10 barevné pozadí.
A2: 2) Vytvořte makro2, které bude vkládat do buněk pod aktivní buňkou čísla 1 až 10000.
A3: 3) Vytvořte commandbutton, který bude přidávat listy s názvy aktuálního data.
A5: Range | D5: value
A6: Cells | D6: formula
A7: ActiveCell | D7: interiror.colorindex
A8: Rows
A9: Columns
A10: Sheets
A11: ActiveSheet

Sheet Tabulka
A1: Rok | B1: Hry | C1: Sport | D1: Disciplína | E1: Umístění | F1: Tým/sportovec | G1: Země | H1: Výsledek
A2: 2004 | B2: Atény | C2: ATLETIKA | D2: 10 000 metrů - ženy | E2: 1 | F2: Chuej-na Sing | G2: Čína | H2: 30:24,36
A3: 2004 | B3: Atény | C3: ATLETIKA | D3: 10 000 metrů - ženy | E3: 2 | F3: Dibabaová Ejegayehu | G3: Etiopie | H3: 30:24,98
A4: 2004 | B4: Atény | C4: ATLETIKA | D4: 10 000 metrů - ženy | E4: 3 | F4: Tuluová Derartu | G4: Etiopie | H4: 30:26,42
A5: 2004 | B5: Atény | C5: SKOKY DO VODY | D5: 10 metrů synchronizované - muži | E5: 1 | F5: Tchien - Jang | G5: Čína | H5: 383,88
A6: 2004 | B6: Atény | C6: SKOKY DO VODY | D6: 10 metrů synchronizované - muži | E6: 2 | F6: Taylor - Waterfield | G6: Velká Británie | H6: 371,52
A7: 2004 | B7: Atény | C7: SKOKY DO VODY | D7: 10 metrů synchronizované - muži | E7: 3 | F7: Helm - Newbery | G7: Austrálie | H7: 366,84
A8: 2004 | B8: Atény | C8: SKOKY DO VODY | D8: 10 metrů synchronizované -ženy | E8: 1 | F8: Li - Li | G8: Čína | H8: 352,14
A9: 2004 | B9: Atény | C9: SKOKY DO VODY | D9: 10 metrů synchronizované -ženy | E9: 2 | F9: Gončarovová - Koltunovová | G9: Rusko | H9: 340,92
A10: 2004 | B10: Atény | C10: SKOKY DO VODY | D10: 10 metrů synchronizované -ženy | E10: 3 | F10: Hartleyová - Heymansová | G10: Kanada | H10: 327,78
A11: 2004 | B11: Atény | C11: PLAVÁNÍ | D11: 100 metrů motýlek - muži | E11: 1 | F11: Phelps Michael | G11: Spojené státy americké | H11: 51,25
A12: 2004 | B12: Atény | C12: PLAVÁNÍ | D12: 100 metrů motýlek - muži | E12: 2 | F12: Crocker Ian | G12: Spojené státy americké | H12: 51,29
A13: 2004 | B13: Atény | C13: PLAVÁNÍ | D13: 100 metrů motýlek - muži | E13: 3 | F13: Serdinov Andrij | G13: Ukrajina | H13: 51,36
... A200: 2004 | B200: Atény | C200: PLAVÁNÍ | D200: 800 metrů volný způsob - ženy | E200: 3 | F200: Munzová Diana | G200: Spojené státy americké | H200: 8:26,61
A201: 2004 | B201: Atény | C201: BOX | D201: Bantamová váha (54 kg) - muži | E201: 1 | F201: Rigondeaux Guillermo | G201: Kuba
A202: 2004 | B202: Atény | C202: BOX | D202: Bantamová váha (54 kg) - muži | E202: 2 | F202: Petchkoom Worapoj | G202: Thajsko
A203: 2004 | B203: Atény | C203: BOX | D203: Bantamová váha (54 kg) - muži | E203: 3 | F203: Mamadov Aghasi | G203: Ázerbajdžán
A204: 2004 | B204: Atény | C204: BOX | D204: Bantamová váha (54 kg) - muži | E204: 3 | F204: Sultanov Bahodirjon | G204: Uzbekistán
A205: 2004 | B205: Atény | C205: VZPÍRÁNÍ | D205: Bantamová váha (56 kg) - muži | E205: 1 | F205: Mutlu Halil | G205: Turecko | H205: 295,0 kg
A206: 2004 | B206: Atény | C206: VZPÍRÁNÍ | D206: Bantamová váha (56 kg) - muži | E206: 2 | F206: Mej-ťin Wu | G206: Čína | H206: 287,5 kg
A207: 2004 | B207: Atény | C207: VZPÍRÁNÍ | D207: Bantamová váha (56 kg) - muži | E207: 3 | F207: Artuc Sedat | G207: Turecko | H207: 280,0 kg
A208: 2004 | B208: Atény | C208: BASEBALL | D208: Baseball - muži | E208: 1 | F208: CUB | G208: Kuba
A209: 2004 | B209: Atény | C209: BASEBALL | D209: Baseball - muži | E209: 2 | F209: AUS | G209: Austrálie
A210: 2004 | B210: Atény | C210: BASEBALL | D210: Baseball - muži | E210: 3 | F210: JPN | G210: Japonsko
A211: 2004 | B211: Atény | C211: BASKETBALL | D211: Basketbal - muži | E211: 1 | F211: ARG | G211: Argentina
A212: 2004 | B212: Atény | C212: BASKETBALL | D212: Basketbal - muži | E212: 2 | F212: ITA | G212: Itálie
A213: 2004 | B213: Atény | C213: BASKETBALL | D213: Basketbal - muži | E213: 3 | F213: USA | G213: Spojené státy americké
A214: 2004 | B214: Atény | C214: BASKETBALL | D214: Basketbal - ženy | E214: 1 | F214: USA | G214: Spojené státy americké
A215: 2004 | B215: Atény | C215: BASKETBALL | D215: Basketbal - ženy | E215: 2 | F215: AUS | G215: Austrálie
A216: 2004 | B216: Atény | C216: BASKETBALL | D216: Basketbal - ženy | E216: 3 | F216: RUS | G216: Rusko
A217: 2004 | B217: Atény | C217: STŘELBA | D217: Běžící terč - muži | E217: 1 | F217: Kurzer Manfred | G217: Německo | H217: 682,4
A218: 2004 | B218: Atény | C218: STŘELBA | D218: Běžící terč - muži | E218: 2 | F218: Blinov Alexandr | G218: Rusko | H218: 678
A219: 2004 | B219: Atény | C219: STŘELBA | D219: Běžící terč - muži | E219: 3 | F219: Lykin Dmitrij | G219: Rusko | H219: 677,1
A220: 2004 | B220: Atény | C220: CYKLISTIKA | D220: Bodovací závod - muži | E220: 1 | F220: Ignatěv Michail | G220: Rusko | H220: 93
A221: 2004 | B221: Atény | C221: CYKLISTIKA | D221: Bodovací závod - muži | E221: 2 | F221: Llaneras Joan | G221: Španělsko | H221: 82
A222: 2004 | B222: Atény | C222: CYKLISTIKA | D222: Bodovací závod - muži | E222: 3 | F222: Fulst Guido | G222: Německo | H222: 79
A223: 2004 | B223: Atény | C223: CYKLISTIKA | D223: Bodovací závod - ženy | E223: 1 | F223: Sljusarevová Olga | G223: Rusko | H223: 20
A224: 2004 | B224: Atény | C224: CYKLISTIKA | D224: Bodovací závod - ženy | E224: 2 | F224: Guerrerová Belem | G224: Mexiko | H224: 14
A225: 2004 | B225: Atény | C225: CYKLISTIKA | D225: Bodovací závod - ženy | E225: 3 | F225: Mirabellaová Erin | G225: Spojené státy americké | H225: 9
A226: 2004 | B226: Atény | C226: CYKLISTIKA | D226: Bodovací závod dvojic - muži | E226: 1 | F226: Brown - O´Grady | G226: Austrálie | H226: 22
...

Sheet Kont01
A3: Počet z Umístění | B3: Popisky sloupců
A4: Popisky řádků | B4: 1 | C4: 2 | D4: 3 | E4: Celkový součet | G4: Země | H4: Zlato | I4: Stříbro | J4: Bronz | K4: Celkem
A5: Argentina | B5: 2 | D5: 4 | E5: 6 | G5: Spojené státy americké | H5: 35 | I5: 39 | J5: 29 | K5: 103
A6: Austrálie | B6: 17 | C6: 17 | D6: 16 | E6: 50 | G6: Čína | H6: 32 | I6: 17 | J6: 14 | K6: 63
A7: Ázerbajdžán | B7: 1 | D7: 4 | E7: 5 | G7: Rusko | H7: 27 | I7: 27 | J7: 38 | K7: 92
A8: Bahamy | B8: 1 | D8: 1 | E8: 2 | G8: Austrálie | H8: 17 | I8: 17 | J8: 16 | K8: 50
A9: Belgie | B9: 1 | D9: 2 | E9: 3 | G9: Japonsko | H9: 16 | I9: 9 | J9: 12 | K9: 37
A10: Bělorusko | B10: 2 | C10: 6 | D10: 7 | E10: 15 | G10: Německo | H10: 14 | I10: 15 | J10: 18 | K10: 47
A11: Brazílie | B11: 4 | C11: 3 | D11: 3 | E11: 10 | G11: Francie | H11: 11 | I11: 10 | J11: 13 | K11: 34
A12: Bulharsko | B12: 2 | C12: 1 | D12: 9 | E12: 12 | G12: Itálie | H12: 10 | I12: 11 | J12: 11 | K12: 32
A13: Česká republika | B13: 1 | C13: 3 | D13: 4 | E13: 8 | G13: Korea | H13: 9 | I13: 12 | J13: 9 | K13: 30
A14: Čína | B14: 32 | C14: 17 | D14: 14 | E14: 63 | G14: Velká Británie | H14: 9 | I14: 9 | J14: 12 | K14: 30
A15: Čína - Taipei | B15: 2 | C15: 1 | D15: 1 | E15: 4 | G15: Kuba | H15: 9 | I15: 7 | J15: 11 | K15: 27
A16: Dánsko | B16: 2 | D16: 7 | E16: 9 | G16: Ukrajina | H16: 9 | I16: 5 | J16: 9 | K16: 23
A17: Dominikánská republika | B17: 1 | E17: 1 | G17: Maďarsko | H17: 8 | I17: 6 | J17: 3 | K17: 17
A18: Egypt | B18: 1 | C18: 1 | D18: 3 | E18: 5 | G18: Rumunsko | H18: 8 | I18: 5 | J18: 6 | K18: 19
A19: Eritrea | D19: 1 | E19: 1 | G19: Řecko | H19: 6 | I19: 7 | J19: 4 | K19: 17
A20: Estonsko | C20: 1 | D20: 2 | E20: 3 | G20: Norsko | H20: 5 | J20: 1 | K20: 6
A21: Etiopie | B21: 2 | C21: 3 | D21: 2 | E21: 7 | G21: Nizozemsko | H21: 4 | I21: 9 | J21: 9 | K21: 22
A22: Finsko | C22: 2 | E22: 2 | G22: Brazílie | H22: 4 | I22: 3 | J22: 3 | K22: 10
A23: Francie | B23: 11 | C23: 10 | D23: 13 | E23: 34 | G23: Švédsko | H23: 4 | I23: 1 | J23: 2 | K23: 7
A24: Gruzie | B24: 2 | C24: 2 | E24: 4 | G24: Španělsko | H24: 3 | I24: 10 | J24: 5 | K24: 18
A25: Hongkong | C25: 1 | E25: 1 | G25: Kanada | H25: 3 | I25: 6 | J25: 3 | K25: 12
A26: Chile | B26: 2 | D26: 1 | E26: 3 | G26: Turecko | H26: 3 | I26: 3 | J26: 4 | K26: 10
A27: Chorvatsko | B27: 1 | C27: 2 | D27: 2 | E27: 5 | G27: Polsko | H27: 3 | I27: 2 | J27: 5 | K27: 10
A28: Indie | C28: 1 | E28: 1 | G28: Nový Zéland | H28: 3 | I28: 2 | K28: 5
A29: Indonésie | B29: 1 | C29: 1 | D29: 1 | E29: 3 | G29: Thajsko | H29: 3 | I29: 1 | J29: 4 | K29: 8
A30: Írán | B30: 2 | C30: 2 | D30: 2 | E30: 6 | G30: Bělorusko | H30: 2 | I30: 6 | J30: 7 | K30: 15
A31: Irsko | B31: 1 | E31: 1 | G31: Etiopie | H31: 2 | I31: 3 | J31: 2 | K31: 7
A32: Itálie | B32: 10 | C32: 11 | D32: 11 | E32: 32 | G32: Rakousko | H32: 2 | I32: 3 | J32: 1 | K32: 6
A33: Izrael | B33: 1 | D33: 1 | E33: 2 | G33: Írán | H33: 2 | I33: 2 | J33: 2 | K33: 6
A34: Jamajka | B34: 2 | C34: 1 | D34: 2 | E34: 5 | G34: Slovensko | H34: 2 | I34: 2 | J34: 2 | K34: 6
A35: Japonsko | B35: 16 | C35: 9 | D35: 12 | E35: 37 | G35: Gruzie | H35: 2 | I35: 2 | K35: 4
A36: Jihoafrická republika | B36: 1 | C36: 3 | D36: 2 | E36: 6 | G36: Bulharsko | H36: 2 | I36: 1 | J36: 9 | K36: 12
A37: Kamerun | B37: 1 | E37: 1 | G37: Jamajka | H37: 2 | I37: 1 | J37: 2 | K37: 5
A38: Kanada | B38: 3 | C38: 6 | D38: 3 | E38: 12 | G38: Uzbekistán | H38: 2 | I38: 1 | J38: 2 | K38: 5
A39: Kazachstán | B39: 1 | C39: 4 | D39: 3 | E39: 8 | G39: Čína - Taipei | H39: 2 | I39: 1 | J39: 1 | K39: 4
A40: Keňa | B40: 1 | C40: 4 | D40: 2 | E40: 7 | G40: Maroko | H40: 2 | I40: 1 | K40: 3
A41: Kolumbie | D41: 1 | E41: 1 | G41: Dánsko | H41: 2 | J41: 7 | K41: 9
A42: Korea | B42: 9 | C42: 12 | D42: 9 | E42: 30 | G42: Argentina | H42: 2 | J42: 4 | K42: 6
...

Sheet Kont02
A3: Popisky řádků | B3: Počet z Umístění
A4: ATLETIKA | B4: 138
A5: PLAVÁNÍ | B5: 97
A6: JUDO | B6: 56
A7: GYMNASTIKA | B7: 54
A8: ZÁPAS | B8: 54
A9: CYKLISTIKA | B9: 54
A10: STŘELBA | B10: 51
A11: KANOISTIKA | B11: 48
A12: VZPÍRÁNÍ | B12: 45
A13: BOX | B13: 44
A14: VESLOVÁNÍ | B14: 42
A15: JACHTING | B15: 33
... A36: Celkový součet | B36: 930

Sheet Kont03
A3: Počet z Umístění | B3: Popisky sloupců
A4: Popisky řádků | B4: 1 | C4: 2 | D4: 3 | E4: Celkový součet
A5: Hod oštěpem - ženy | B5: 1 | C5: 1 | D5: 1 | E5: 3
A6: Hod oštěpem muži | B6: 1 | C6: 1 | D6: 1 | E6: 3
A7: Celkový součet | B7: 2 | C7: 2 | D7: 2 | E7: 6

Sheet Kont04
A4: Počet z Výsledek | B4: Popisky sloupců
A5: Popisky řádků | B5: 1:00,37OR | C5: 1:57,14OR | D5: 1:58,03WR | E5: 272,5OR | F5: 57,72WR | G5: Celkový součet
A6: PLAVÁNÍ | B6: 1 | C6: 1 | D6: 1 | F6: 1 | G6: 4
A7: Austrálie | F7: 1 | G7: 1
A8: Rumunsko | D8: 1 | G8: 1
A9: Spojené státy americké | B9: 1 | C9: 1 | G9: 2
A10: VZPÍRÁNÍ | E10: 1 | G10: 1
A11: Thajsko | E11: 1 | G11: 1
A12: Celkový součet | B12: 1 | C12: 1 | D12: 1 | E12: 1 | F12: 1 | G12: 5
